import { InferableError } from "./errors";
import { serializeError } from "./serialize-error";
import { FunctionRegistration } from "./types";

export type Result<T = unknown> = {
  content: T;
  type: "resolution" | "rejection";
  functionExecutionTime?: number;
};

export const executeFn = async (
  fn: FunctionRegistration["func"],
  args: Parameters<FunctionRegistration["func"]>,
  authenticate?: (
    authContext: string,
    args: Parameters<FunctionRegistration["func"]>["0"],
  ) => Promise<void>,
  authContext?: string,
): Promise<Result> => {
  const start = Date.now();
  try {
    if (authenticate) {
      if (!authContext) {
        throw new InferableError(InferableError.JOB_AUTHCONTEXT_INVALID);
      }

      await authenticate(authContext, args[0]);
    }

    const result = await fn(...args);

    return {
      content: result,
      type: "resolution",
      functionExecutionTime: Date.now() - start,
    };
  } catch (e) {
    const functionExecutionTime = Date.now() - start;
    if (e instanceof Error) {
      return {
        content: serializeError(e),
        type: "rejection",
        functionExecutionTime,
      };
    } else if (typeof e === "string") {
      return {
        content: serializeError(new Error(e)),
        type: "rejection",
        functionExecutionTime,
      };
    } else {
      return {
        content: new Error(
          "Inferable encountered an unexpected error type. Make sure you are throwing an Error object.",
        ),
        type: "rejection",
        functionExecutionTime,
      };
    }
  }
};
